Workbook

Sheet 🏠 Accueil
B2: DEBLOCAR
B3: Système de Suivi des Leads — Version 3
B6: 📁 Structure du fichier
B7: 🏠 Accueil → Cette page.
B8: 📊 Dashboard → KPIs automatiques : total leads, RDV, statuts, sources, modèles, volume mensuel.
B9: 📅 Janvier → Décembre → Un onglet par mois. Saisir les leads ici.
B10: _Listes → Onglet caché — source des listes déroulantes.
B12: 🆕 Champs avec sélection (v3)
B13: Statut → 9 statuts du tunnel commercial (liste déroulante).
B14: Gouvernorat → 24 gouvernorats de Tunisie (liste déroulante).
B15: Source du lead → WhatsApp / Instagram / Messenger / Appel direct / TikTok / Facebook / Autre.
B16: Modèle véhicule → Liste complète BMW, Mercedes, VW, Audi, Cupra, Kia, BYD, Volvo, Autre.
... B37: deblocar.com • Document interne • v3

Sheet Feuille 1

Sheet _Listes
A1: Statuts | B1: Gouvernorats | C1: Sources | D1: Modèles | E1: Services
A2: Nouveau lead | B2: Ariana | C2: WhatsApp | D2: BMW Serie 1 | E2: Navigation GPS
A3: Appel 1 effectué | B3: Béja | C3: Instagram | D3: BMW Serie 2 | E3: Apple CarPlay
A4: En attente VIN/Photo | B4: Ben Arous | C4: Messenger | D4: BMW Serie 3 | E4: Android Auto
A5: Vérification | B5: Bizerte | C5: Appel direct | D5: BMW Serie 4 | E5: Activation alarme
A6: Appel 2 effectué | B6: Gabès | C6: TikTok | D6: BMW Serie 5 | E6: Pack AMG
A7: RDV confirmé | B7: Gafsa | C7: Facebook | D7: BMW Serie 7 | E7: Pack M
A8: RDV honoré | B8: Jendouba | C8: Autre | D8: BMW X1 | E8: Pack R
A9: Non faisable | B9: Kairouan | D9: BMW X3 | E9: Codage d'options
A10: Annulé | B10: Kasserine | D10: BMW X5 | E10: Mise à jour logicielle
B11: Kébili | D11: BMW X6 | E11: Navigation + Apple CarPlay
B12: Le Kef | D12: Mercedes Classe A | E12: Navigation + CarPlay + Alarme
B13: Mahdia | D13: Mercedes Classe B | E13: Navigation + Pack AMG
B14: La Manouba | D14: Mercedes Classe C | E14: Fonctions cachées
B15: Médenine | D15: Mercedes Classe E | E15: Autre
B16: Monastir | D16: Mercedes Classe S
B17: Nabeul | D17: Mercedes GLA
B18: Sfax | D18: Mercedes GLB
B19: Sidi Bouzid | D19: Mercedes GLC
B20: Siliana | D20: Mercedes GLE
B21: Sousse | D21: Mercedes GLS
B22: Tataouine | D22: VW Golf 7
B23: Tozeur | D23: VW Golf 8
B24: Tunis | D24: VW Tiguan
B25: Zaghouan | D25: VW T-Cross
D26: VW Passat
D27: VW Polo
D28: Audi A1
D29: Audi A3
D30: Audi A4
D31: Audi A5
D32: Audi A6
D33: Audi Q3
D34: Audi Q5
D35: Audi Q7
D36: Cupra Formentor
D37: Cupra Leon
... D42: Autre

Sheet 📊 Dashboard
B1: 📊 DEBLOCAR — Dashboard Commercial 2025
B2: Mise à jour automatique · Données agrégées depuis les 12 onglets mensuels
B5: 📥 Total Leads | E5: ✅ RDV Honorés | H5: 🔑 Codes Activés
B6: =COUNTA('📅 Janvier'!A4:A500)+COUNTA('📅 Février'!A4:A500)+COUNTA('📅 Mars'!A4:A500)+COUNTA('📅 Avril'!A4:A500)+COUNTA('📅 Mai'!A4:A500)+COUNTA('📅 Juin'!A4:A520)+COUNTA('📅 Juillet'!A4:A522)+COUNTA('📅 Août'!A4:A508)+COUNTA('📅 Septembre'!A6:A500)+COUNTA('📅 Octobre'!A4:A500)+COUNTA('📅 Novembre'!A4:A500)+COUNTA('📅 Décembre'!A4:A500) -> 134 | E6: =COUNTIF('📅 Janvier'!$K:$K,"RDV honoré")+COUNTIF('📅 Février'!$K:$K,"RDV honoré")+COUNTIF('📅 Mars'!$K:$K,"RDV honoré")+COUNTIF('📅 Avril'!$K:$K,"RDV honoré")+COUNTIF('📅 Mai'!$K:$K,"RDV honoré")+COUNTIF('📅 Juin'!$K:$K,"RDV honoré")+COUNTIF('📅 Juillet'!$K:$K,"RDV honoré")+COUNTIF('📅 Août'!$K:$K,"RDV honoré")+COUNTIF('📅 Septembre'!$K:$K,"RDV honoré")+COUNTIF('📅 Octobre'!$K:$K,"RDV honoré")+COUNTIF('📅 Novembre'!$K:$K,"RDV honoré")+COUNTIF('📅 Décembre'!$K:$K,"RDV honoré") -> 1 | H6: =COUNTA('📅 Janvier'!$I4:$I500)+COUNTA('📅 Février'!$I4:$I500)+COUNTA('📅 Mars'!$I4:$I500)+COUNTA('📅 Avril'!$I4:$I500)+COUNTA('📅 Mai'!$I4:$I500)+COUNTA('📅 Juin'!$I4:$I520)+COUNTA('📅 Juillet'!$I4:$I522)+COUNTA('📅 Août'!$I4:$I508)+COUNTA('📅 Septembre'!$I6:$I500)+COUNTA('📅 Octobre'!$I4:$I500)+COUNTA('📅 Novembre'!$I4:$I500)+COUNTA('📅 Décembre'!$I4:$I500) -> 0
B9: 📈 Taux de transformation | D9: =IF((COUNTA('📅 Janvier'!A4:A500)+COUNTA('📅 Février'!A4:A500)+COUNTA('📅 Mars'!A4:A500)+COUNTA('📅 Avril'!A4:A500)+COUNTA('📅 Mai'!A4:A500)+COUNTA('📅 Juin'!A4:A520)+COUNTA('📅 Juillet'!A4:A522)+COUNTA('📅 Août'!A4:A508)+COUNTA('📅 Septembre'!A6:A500)+COUNTA('📅 Octobre'!A4:A500)+COUNTA('📅 Novembre'!A4:A500)+COUNTA('📅 Décembre'!A4:A500))=0,"—",TEXT((COUNTIF('📅 Janvier'!$K:$K,"RDV honoré")+COUNTIF('📅 Février'!$K:$K,"RDV honoré")+COUNTIF('📅 Mars'!$K:$K,"RDV honoré")+COUNTIF('📅 Avril'!$K:$K,"RDV honoré")+COUNTIF('📅 Mai'!$K:$K,"RDV honoré")+COUNTIF('📅 Juin'!$K:$K,"RDV honoré")+COUNTIF('📅 Juillet'!$K:$K,"RDV honoré")+COUNTIF('📅 Août'!$K:$K,"RDV honoré")+COUNTIF('📅 Septembre'!$K:$K,"RDV honoré")+COUNTIF('📅 Octobre'!$K:$K,"RDV honoré")+COUNTIF('📅 Novembre'!$K:$K,"RDV honoré")+COUNTIF('📅 Décembre'!$K:$K,"RDV honoré"))/(COUNTA('📅 Janvier'!A4:A500)+COUNTA('📅 Février'!A4:A500)+COUNTA('📅 Mars'!A4:A500)+COUNTA('📅 Avril'!A4:A500)+COUNTA('📅 Mai'!A4:A500)+COUNTA('📅 Juin'!A4:A520)+COUNTA('📅 Juillet'!A4:A522)+COUNTA('📅 Août'!A4:A508)+COUNTA('📅 Septembre'!A6:A500)+COUNTA('📅 Octobre'!A4:A500)+COUNTA('📅 Novembre'!A4:A500)+COUNTA('📅 Décembre'!A4:A500)),"0.0%")) -> 0,7% | G9: RDV honorés ÷ Total leads
B11: 📋 Répartition par Statut | E11: 📱 Source des leads
B12: Statut | C12: Leads | E12: Source | F12: Leads
B13: Nouveau lead | C13: =COUNTIF('📅 Janvier'!$K:$K,"Nouveau lead")+COUNTIF('📅 Février'!$K:$K,"Nouveau lead")+COUNTIF('📅 Mars'!$K:$K,"Nouveau lead")+COUNTIF('📅 Avril'!$K:$K,"Nouveau lead")+COUNTIF('📅 Mai'!$K:$K,"Nouveau lead")+COUNTIF('📅 Juin'!$K:$K,"Nouveau lead")+COUNTIF('📅 Juillet'!$K:$K,"Nouveau lead")+COUNTIF('📅 Août'!$K:$K,"Nouveau lead")+COUNTIF('📅 Septembre'!$K:$K,"Nouveau lead")+COUNTIF('📅 Octobre'!$K:$K,"Nouveau lead")+COUNTIF('📅 Novembre'!$K:$K,"Nouveau lead")+COUNTIF('📅 Décembre'!$K:$K,"Nouveau lead") -> 37 | E13: WhatsApp | F13: =COUNTIF('📅 Janvier'!$C:$C,"WhatsApp")+COUNTIF('📅 Février'!$C:$C,"WhatsApp")+COUNTIF('📅 Mars'!$C:$C,"WhatsApp")+COUNTIF('📅 Avril'!$C:$C,"WhatsApp")+COUNTIF('📅 Mai'!$C:$C,"WhatsApp")+COUNTIF('📅 Juin'!$C:$C,"WhatsApp")+COUNTIF('📅 Juillet'!$C:$C,"WhatsApp")+COUNTIF('📅 Août'!$C:$C,"WhatsApp")+COUNTIF('📅 Septembre'!$C:$C,"WhatsApp")+COUNTIF('📅 Octobre'!$C:$C,"WhatsApp")+COUNTIF('📅 Novembre'!$C:$C,"WhatsApp")+COUNTIF('📅 Décembre'!$C:$C,"WhatsApp") -> 54
B14: Appel 1 effectué | C14: =COUNTIF('📅 Janvier'!$K:$K,"Appel 1 effectué")+COUNTIF('📅 Février'!$K:$K,"Appel 1 effectué")+COUNTIF('📅 Mars'!$K:$K,"Appel 1 effectué")+COUNTIF('📅 Avril'!$K:$K,"Appel 1 effectué")+COUNTIF('📅 Mai'!$K:$K,"Appel 1 effectué")+COUNTIF('📅 Juin'!$K:$K,"Appel 1 effectué")+COUNTIF('📅 Juillet'!$K:$K,"Appel 1 effectué")+COUNTIF('📅 Août'!$K:$K,"Appel 1 effectué")+COUNTIF('📅 Septembre'!$K:$K,"Appel 1 effectué")+COUNTIF('📅 Octobre'!$K:$K,"Appel 1 effectué")+COUNTIF('📅 Novembre'!$K:$K,"Appel 1 effectué")+COUNTIF('📅 Décembre'!$K:$K,"Appel 1 effectué") -> 1 | E14: Instagram | F14: =COUNTIF('📅 Janvier'!$C:$C,"Instagram")+COUNTIF('📅 Février'!$C:$C,"Instagram")+COUNTIF('📅 Mars'!$C:$C,"Instagram")+COUNTIF('📅 Avril'!$C:$C,"Instagram")+COUNTIF('📅 Mai'!$C:$C,"Instagram")+COUNTIF('📅 Juin'!$C:$C,"Instagram")+COUNTIF('📅 Juillet'!$C:$C,"Instagram")+COUNTIF('📅 Août'!$C:$C,"Instagram")+COUNTIF('📅 Septembre'!$C:$C,"Instagram")+COUNTIF('📅 Octobre'!$C:$C,"Instagram")+COUNTIF('📅 Novembre'!$C:$C,"Instagram")+COUNTIF('📅 Décembre'!$C:$C,"Instagram") -> 26
B15: En attente VIN/Photo | C15: =COUNTIF('📅 Janvier'!$K:$K,"En attente VIN/Photo")+COUNTIF('📅 Février'!$K:$K,"En attente VIN/Photo")+COUNTIF('📅 Mars'!$K:$K,"En attente VIN/Photo")+COUNTIF('📅 Avril'!$K:$K,"En attente VIN/Photo")+COUNTIF('📅 Mai'!$K:$K,"En attente VIN/Photo")+COUNTIF('📅 Juin'!$K:$K,"En attente VIN/Photo")+COUNTIF('📅 Juillet'!$K:$K,"En attente VIN/Photo")+COUNTIF('📅 Août'!$K:$K,"En attente VIN/Photo")+COUNTIF('📅 Septembre'!$K:$K,"En attente VIN/Photo")+COUNTIF('📅 Octobre'!$K:$K,"En attente VIN/Photo")+COUNTIF('📅 Novembre'!$K:$K,"En attente VIN/Photo")+COUNTIF('📅 Décembre'!$K:$K,"En attente VIN/Photo") -> 14 | E15: Messenger | F15: =COUNTIF('📅 Janvier'!$C:$C,"Messenger")+COUNTIF('📅 Février'!$C:$C,"Messenger")+COUNTIF('📅 Mars'!$C:$C,"Messenger")+COUNTIF('📅 Avril'!$C:$C,"Messenger")+COUNTIF('📅 Mai'!$C:$C,"Messenger")+COUNTIF('📅 Juin'!$C:$C,"Messenger")+COUNTIF('📅 Juillet'!$C:$C,"Messenger")+COUNTIF('📅 Août'!$C:$C,"Messenger")+COUNTIF('📅 Septembre'!$C:$C,"Messenger")+COUNTIF('📅 Octobre'!$C:$C,"Messenger")+COUNTIF('📅 Novembre'!$C:$C,"Messenger")+COUNTIF('📅 Décembre'!$C:$C,"Messenger") -> 65
B16: Vérification | C16: =COUNTIF('📅 Janvier'!$K:$K,"Vérification")+COUNTIF('📅 Février'!$K:$K,"Vérification")+COUNTIF('📅 Mars'!$K:$K,"Vérification")+COUNTIF('📅 Avril'!$K:$K,"Vérification")+COUNTIF('📅 Mai'!$K:$K,"Vérification")+COUNTIF('📅 Juin'!$K:$K,"Vérification")+COUNTIF('📅 Juillet'!$K:$K,"Vérification")+COUNTIF('📅 Août'!$K:$K,"Vérification")+COUNTIF('📅 Septembre'!$K:$K,"Vérification")+COUNTIF('📅 Octobre'!$K:$K,"Vérification")+COUNTIF('📅 Novembre'!$K:$K,"Vérification")+COUNTIF('📅 Décembre'!$K:$K,"Vérification") -> 11 | E16: Appel direct | F16: =COUNTIF('📅 Janvier'!$C:$C,"Appel direct")+COUNTIF('📅 Février'!$C:$C,"Appel direct")+COUNTIF('📅 Mars'!$C:$C,"Appel direct")+COUNTIF('📅 Avril'!$C:$C,"Appel direct")+COUNTIF('📅 Mai'!$C:$C,"Appel direct")+COUNTIF('📅 Juin'!$C:$C,"Appel direct")+COUNTIF('📅 Juillet'!$C:$C,"Appel direct")+COUNTIF('📅 Août'!$C:$C,"Appel direct")+COUNTIF('📅 Septembre'!$C:$C,"Appel direct")+COUNTIF('📅 Octobre'!$C:$C,"Appel direct")+COUNTIF('📅 Novembre'!$C:$C,"Appel direct")+COUNTIF('📅 Décembre'!$C:$C,"Appel direct") -> 7
B17: Appel 2 effectué | C17: =COUNTIF('📅 Janvier'!$K:$K,"Appel 2 effectué")+COUNTIF('📅 Février'!$K:$K,"Appel 2 effectué")+COUNTIF('📅 Mars'!$K:$K,"Appel 2 effectué")+COUNTIF('📅 Avril'!$K:$K,"Appel 2 effectué")+COUNTIF('📅 Mai'!$K:$K,"Appel 2 effectué")+COUNTIF('📅 Juin'!$K:$K,"Appel 2 effectué")+COUNTIF('📅 Juillet'!$K:$K,"Appel 2 effectué")+COUNTIF('📅 Août'!$K:$K,"Appel 2 effectué")+COUNTIF('📅 Septembre'!$K:$K,"Appel 2 effectué")+COUNTIF('📅 Octobre'!$K:$K,"Appel 2 effectué")+COUNTIF('📅 Novembre'!$K:$K,"Appel 2 effectué")+COUNTIF('📅 Décembre'!$K:$K,"Appel 2 effectué") -> 0 | E17: TikTok | F17: =COUNTIF('📅 Janvier'!$C:$C,"TikTok")+COUNTIF('📅 Février'!$C:$C,"TikTok")+COUNTIF('📅 Mars'!$C:$C,"TikTok")+COUNTIF('📅 Avril'!$C:$C,"TikTok")+COUNTIF('📅 Mai'!$C:$C,"TikTok")+COUNTIF('📅 Juin'!$C:$C,"TikTok")+COUNTIF('📅 Juillet'!$C:$C,"TikTok")+COUNTIF('📅 Août'!$C:$C,"TikTok")+COUNTIF('📅 Septembre'!$C:$C,"TikTok")+COUNTIF('📅 Octobre'!$C:$C,"TikTok")+COUNTIF('📅 Novembre'!$C:$C,"TikTok")+COUNTIF('📅 Décembre'!$C:$C,"TikTok") -> 0
B18: RDV confirmé | C18: =COUNTIF('📅 Janvier'!$K:$K,"RDV confirmé")+COUNTIF('📅 Février'!$K:$K,"RDV confirmé")+COUNTIF('📅 Mars'!$K:$K,"RDV confirmé")+COUNTIF('📅 Avril'!$K:$K,"RDV confirmé")+COUNTIF('📅 Mai'!$K:$K,"RDV confirmé")+COUNTIF('📅 Juin'!$K:$K,"RDV confirmé")+COUNTIF('📅 Juillet'!$K:$K,"RDV confirmé")+COUNTIF('📅 Août'!$K:$K,"RDV confirmé")+COUNTIF('📅 Septembre'!$K:$K,"RDV confirmé")+COUNTIF('📅 Octobre'!$K:$K,"RDV confirmé")+COUNTIF('📅 Novembre'!$K:$K,"RDV confirmé")+COUNTIF('📅 Décembre'!$K:$K,"RDV confirmé") -> 55 | E18: Facebook | F18: =COUNTIF('📅 Janvier'!$C:$C,"Facebook")+COUNTIF('📅 Février'!$C:$C,"Facebook")+COUNTIF('📅 Mars'!$C:$C,"Facebook")+COUNTIF('📅 Avril'!$C:$C,"Facebook")+COUNTIF('📅 Mai'!$C:$C,"Facebook")+COUNTIF('📅 Juin'!$C:$C,"Facebook")+COUNTIF('📅 Juillet'!$C:$C,"Facebook")+COUNTIF('📅 Août'!$C:$C,"Facebook")+COUNTIF('📅 Septembre'!$C:$C,"Facebook")+COUNTIF('📅 Octobre'!$C:$C,"Facebook")+COUNTIF('📅 Novembre'!$C:$C,"Facebook")+COUNTIF('📅 Décembre'!$C:$C,"Facebook") -> 0
B19: RDV honoré | C19: =COUNTIF('📅 Janvier'!$K:$K,"RDV honoré")+COUNTIF('📅 Février'!$K:$K,"RDV honoré")+COUNTIF('📅 Mars'!$K:$K,"RDV honoré")+COUNTIF('📅 Avril'!$K:$K,"RDV honoré")+COUNTIF('📅 Mai'!$K:$K,"RDV honoré")+COUNTIF('📅 Juin'!$K:$K,"RDV honoré")+COUNTIF('📅 Juillet'!$K:$K,"RDV honoré")+COUNTIF('📅 Août'!$K:$K,"RDV honoré")+COUNTIF('📅 Septembre'!$K:$K,"RDV honoré")+COUNTIF('📅 Octobre'!$K:$K,"RDV honoré")+COUNTIF('📅 Novembre'!$K:$K,"RDV honoré")+COUNTIF('📅 Décembre'!$K:$K,"RDV honoré") -> 1 | E19: Autre | F19: =COUNTIF('📅 Janvier'!$C:$C,"Autre")+COUNTIF('📅 Février'!$C:$C,"Autre")+COUNTIF('📅 Mars'!$C:$C,"Autre")+COUNTIF('📅 Avril'!$C:$C,"Autre")+COUNTIF('📅 Mai'!$C:$C,"Autre")+COUNTIF('📅 Juin'!$C:$C,"Autre")+COUNTIF('📅 Juillet'!$C:$C,"Autre")+COUNTIF('📅 Août'!$C:$C,"Autre")+COUNTIF('📅 Septembre'!$C:$C,"Autre")+COUNTIF('📅 Octobre'!$C:$C,"Autre")+COUNTIF('📅 Novembre'!$C:$C,"Autre")+COUNTIF('📅 Décembre'!$C:$C,"Autre") -> 0
B20: Non faisable | C20: =COUNTIF('📅 Janvier'!$K:$K,"Non faisable")+COUNTIF('📅 Février'!$K:$K,"Non faisable")+COUNTIF('📅 Mars'!$K:$K,"Non faisable")+COUNTIF('📅 Avril'!$K:$K,"Non faisable")+COUNTIF('📅 Mai'!$K:$K,"Non faisable")+COUNTIF('📅 Juin'!$K:$K,"Non faisable")+COUNTIF('📅 Juillet'!$K:$K,"Non faisable")+COUNTIF('📅 Août'!$K:$K,"Non faisable")+COUNTIF('📅 Septembre'!$K:$K,"Non faisable")+COUNTIF('📅 Octobre'!$K:$K,"Non faisable")+COUNTIF('📅 Novembre'!$K:$K,"Non faisable")+COUNTIF('📅 Décembre'!$K:$K,"Non faisable") -> 6
B21: Annulé | C21: =COUNTIF('📅 Janvier'!$K:$K,"Annulé")+COUNTIF('📅 Février'!$K:$K,"Annulé")+COUNTIF('📅 Mars'!$K:$K,"Annulé")+COUNTIF('📅 Avril'!$K:$K,"Annulé")+COUNTIF('📅 Mai'!$K:$K,"Annulé")+COUNTIF('📅 Juin'!$K:$K,"Annulé")+COUNTIF('📅 Juillet'!$K:$K,"Annulé")+COUNTIF('📅 Août'!$K:$K,"Annulé")+COUNTIF('📅 Septembre'!$K:$K,"Annulé")+COUNTIF('📅 Octobre'!$K:$K,"Annulé")+COUNTIF('📅 Novembre'!$K:$K,"Annulé")+COUNTIF('📅 Décembre'!$K:$K,"Annulé") -> 6
B24: 📅 Volume mensuel des leads
B25: Jan | C25: Fév | D25: Mar | E25: Avr | F25: Mai | G25: Jun | H25: Jul | I25: Aoû | J25: Sep | K25: Oct | L25: Nov | M25: Déc
B26: =COUNTA('📅 Janvier'!A4:A500) -> 0 | C26: =COUNTA('📅 Février'!A4:A500) -> 0 | D26: =COUNTA('📅 Mars'!A4:A500) -> 0 | E26: =COUNTA('📅 Avril'!A4:A500) -> 0 | F26: =COUNTA('📅 Mai'!A4:A500) -> 0 | G26: =COUNTA('📅 Juin'!A4:A520) -> 54 | H26: =COUNTA('📅 Juillet'!A4:A522) -> 53 | I26: =COUNTA('📅 Août'!A4:A508) -> 22 | J26: =COUNTA('📅 Septembre'!A6:A500) -> 5 | K26: =COUNTA('📅 Octobre'!A4:A500) -> 0 | L26: =COUNTA('📅 Novembre'!A4:A500) -> 0 | M26: =COUNTA('📅 Décembre'!A4:A500) -> 0
B28: 🚗 Leads par marque
B29: Marque | C29: Leads
B30: BMW | C30: =COUNTIF('📅 Janvier'!$E:$E,"*BMW*")+COUNTIF('📅 Février'!$E:$E,"*BMW*")+COUNTIF('📅 Mars'!$E:$E,"*BMW*")+COUNTIF('📅 Avril'!$E:$E,"*BMW*")+COUNTIF('📅 Mai'!$E:$E,"*BMW*")+COUNTIF('📅 Juin'!$E:$E,"*BMW*")+COUNTIF('📅 Juillet'!$E:$E,"*BMW*")+COUNTIF('📅 Août'!$E:$E,"*BMW*")+COUNTIF('📅 Septembre'!$E:$E,"*BMW*")+COUNTIF('📅 Octobre'!$E:$E,"*BMW*")+COUNTIF('📅 Novembre'!$E:$E,"*BMW*")+COUNTIF('📅 Décembre'!$E:$E,"*BMW*") -> 32
B31: Mercedes | C31: =COUNTIF('📅 Janvier'!$E:$E,"*Mercedes*")+COUNTIF('📅 Février'!$E:$E,"*Mercedes*")+COUNTIF('📅 Mars'!$E:$E,"*Mercedes*")+COUNTIF('📅 Avril'!$E:$E,"*Mercedes*")+COUNTIF('📅 Mai'!$E:$E,"*Mercedes*")+COUNTIF('📅 Juin'!$E:$E,"*Mercedes*")+COUNTIF('📅 Juillet'!$E:$E,"*Mercedes*")+COUNTIF('📅 Août'!$E:$E,"*Mercedes*")+COUNTIF('📅 Septembre'!$E:$E,"*Mercedes*")+COUNTIF('📅 Octobre'!$E:$E,"*Mercedes*")+COUNTIF('📅 Novembre'!$E:$E,"*Mercedes*")+COUNTIF('📅 Décembre'!$E:$E,"*Mercedes*") -> 70
B32: Volkswagen | C32: =COUNTIF('📅 Janvier'!$E:$E,"*VW*")+COUNTIF('📅 Février'!$E:$E,"*VW*")+COUNTIF('📅 Mars'!$E:$E,"*VW*")+COUNTIF('📅 Avril'!$E:$E,"*VW*")+COUNTIF('📅 Mai'!$E:$E,"*VW*")+COUNTIF('📅 Juin'!$E:$E,"*VW*")+COUNTIF('📅 Juillet'!$E:$E,"*VW*")+COUNTIF('📅 Août'!$E:$E,"*VW*")+COUNTIF('📅 Septembre'!$E:$E,"*VW*")+COUNTIF('📅 Octobre'!$E:$E,"*VW*")+COUNTIF('📅 Novembre'!$E:$E,"*VW*")+COUNTIF('📅 Décembre'!$E:$E,"*VW*") -> 16
B33: Audi | C33: =COUNTIF('📅 Janvier'!$E:$E,"*Audi*")+COUNTIF('📅 Février'!$E:$E,"*Audi*")+COUNTIF('📅 Mars'!$E:$E,"*Audi*")+COUNTIF('📅 Avril'!$E:$E,"*Audi*")+COUNTIF('📅 Mai'!$E:$E,"*Audi*")+COUNTIF('📅 Juin'!$E:$E,"*Audi*")+COUNTIF('📅 Juillet'!$E:$E,"*Audi*")+COUNTIF('📅 Août'!$E:$E,"*Audi*")+COUNTIF('📅 Septembre'!$E:$E,"*Audi*")+COUNTIF('📅 Octobre'!$E:$E,"*Audi*")+COUNTIF('📅 Novembre'!$E:$E,"*Audi*")+COUNTIF('📅 Décembre'!$E:$E,"*Audi*") -> 15
B34: Cupra | C34: =COUNTIF('📅 Janvier'!$E:$E,"*Cupra*")+COUNTIF('📅 Février'!$E:$E,"*Cupra*")+COUNTIF('📅 Mars'!$E:$E,"*Cupra*")+COUNTIF('📅 Avril'!$E:$E,"*Cupra*")+COUNTIF('📅 Mai'!$E:$E,"*Cupra*")+COUNTIF('📅 Juin'!$E:$E,"*Cupra*")+COUNTIF('📅 Juillet'!$E:$E,"*Cupra*")+COUNTIF('📅 Août'!$E:$E,"*Cupra*")+COUNTIF('📅 Septembre'!$E:$E,"*Cupra*")+COUNTIF('📅 Octobre'!$E:$E,"*Cupra*")+COUNTIF('📅 Novembre'!$E:$E,"*Cupra*")+COUNTIF('📅 Décembre'!$E:$E,"*Cupra*") -> 1
B35: Autres | C35: =(COUNTA('📅 Janvier'!A4:A500)+COUNTA('📅 Février'!A4:A500)+COUNTA('📅 Mars'!A4:A500)+COUNTA('📅 Avril'!A4:A500)+COUNTA('📅 Mai'!A4:A500)+COUNTA('📅 Juin'!A4:A520)+COUNTA('📅 Juillet'!A4:A522)+COUNTA('📅 Août'!A4:A508)+COUNTA('📅 Septembre'!A6:A500)+COUNTA('📅 Octobre'!A4:A500)+COUNTA('📅 Novembre'!A4:A500)+COUNTA('📅 Décembre'!A4:A500))-(COUNTIF('📅 Janvier'!$E:$E,"*BMW*")+COUNTIF('📅 Janvier'!$E:$E,"*Mercedes*")+COUNTIF('📅 Janvier'!$E:$E,"*VW*")+COUNTIF('📅 Janvier'!$E:$E,"*Audi*")+COUNTIF('📅 Janvier'!$E:$E,"*Cupra*")+COUNTIF('📅 Février'!$E:$E,"*BMW*")+COUNTIF('📅 Février'!$E:$E,"*Mercedes*")+COUNTIF('📅 Février'!$E:$E,"*VW*")+COUNTIF('📅 Février'!$E:$E,"*Audi*")+COUNTIF('📅 Février'!$E:$E,"*Cupra*")+COUNTIF('📅 Mars'!$E:$E,"*BMW*")+COUNTIF('📅 Mars'!$E:$E,"*Mercedes*")+COUNTIF('📅 Mars'!$E:$E,"*VW*")+COUNTIF('📅 Mars'!$E:$E,"*Audi*")+COUNTIF('📅 Mars'!$E:$E,"*Cupra*")+COUNTIF('📅 Avril'!$E:$E,"*BMW*")+COUNTIF('📅 Avril'!$E:$E,"*Mercedes*")+COUNTIF('📅 Avril'!$E:$E,"*VW*")+COUNTIF('📅 Avril'!$E:$E,"*Audi*")+COUNTIF('📅 Avril'!$E:$E,"*Cupra*")+COUNTIF('📅 Mai'!$E:$E,"*BMW*")+COUNTIF('📅 Mai'!$E:$E,"*Mercedes*")+COUNTIF('📅 Mai'!$E:$E,"*VW*")+COUNTIF('📅 Mai'!$E:$E,"*Audi*")+COUNTIF('📅 Mai'!$E:$E,"*Cupra*")+COUNTIF('📅 Juin'!$E:$E,"*BMW*")+COUNTIF('📅 Juin'!$E:$E,"*Mercedes*")+COUNTIF('📅 Juin'!$E:$E,"*VW*")+COUNTIF('📅 Juin'!$E:$E,"*Audi*")+COUNTIF('📅 Juin'!$E:$E,"*Cupra*")+COUNTIF('📅 Juillet'!$E:$E,"*BMW*")+COUNTIF('📅 Juillet'!$E:$E,"*Mercedes*")+COUNTIF('📅 Juillet'!$E:$E,"*VW*")+COUNTIF('📅 Juillet'!$E:$E,"*Audi*")+COUNTIF('📅 Juillet'!$E:$E,"*Cupra*")+COUNTIF('📅 Août'!$E:$E,"*BMW*")+COUNTIF('📅 Août'!$E:$E,"*Mercedes*")+COUNTIF('📅 Août'!$E:$E,"*VW*")+COUNTIF('📅 Août'!$E:$E,"*Audi*")+COUNTIF('📅 Août'!$E:$E,"*Cupra*")+COUNTIF('📅 Septembre'!$E:$E,"*BMW*")+COUNTIF('📅 Septembre'!$E:$E,"*Mercedes*")+COUNTIF('📅 Septembre'!$E:$E,"*VW*")+COUNTIF('📅 Septembre'!$E:$E,"*Audi*")+COUNTIF('📅 Septembre'!$E:$E,"*Cupra*")+COUNTIF('📅 Octobre'!$E:$E,"*BMW*")+COUNTIF('📅 Octobre'!$E:$E,"*Mercedes*")+COUNTIF('📅 Octobre'!$E:$E,"*VW*")+COUNTIF('📅 Octobre'!$E:$E,"*Audi*")+COUNTIF('📅 Octobre'!$E:$E,"*Cupra*")+COUNTIF('📅 Novembre'!$E:$E,"*BMW*")+COUNTIF('📅 Novembre'!$E:$E,"*Mercedes*")+COUNTIF('📅 Novembre'!$E:$E,"*VW*")+COUNTIF('📅 Novembre'!$E:$E,"*Audi*")+COUNTIF('📅 Novembre'!$E:$E,"*Cupra*")+COUNTIF('📅 Décembre'!$E:$E,"*BMW*")+COUNTIF('📅 Décembre'!$E:$E,"*Mercedes*")+COUNTIF('📅 Décembre'!$E:$E,"*VW*")+COUNTIF('📅 Décembre'!$E:$E,"*Audi*")+COUNTIF('📅 Décembre'!$E:$E,"*Cupra*")) -> 0
B38: deblocar.com • Document interne Deblocar • Version 3

Sheet 📅 Janvier
A1: DEBLOCAR — Suivi leads | Janvier
A2: Nouveau lead | B2: Appel 1 effectué | C2: En attente VIN/Photo | D2: Vérification | E2: Appel 2 effectué | F2: RDV confirmé | G2: RDV honoré | H2: Non faisable | I2: Annulé
A3: Nom | B3: Téléphone | C3: Source du lead | D3: Gouvernorat | E3: Modèle véhicule | F3: Service demandé | G3: N° Châssis (VIN) | H3: Modèle de poste | I3: Code Activation | J3: Date RDV | K3: Statut | L3: Confirm. J-1 | M3: Notes
A502: 💡 BMW/Mercedes → N° Châssis (VIN) | VW/Audi/Cupra → Modèle de poste | Code Activation = code licence acheté | Date RDV : format JJ/MM/AAAA

Sheet 📅 Février
A1: DEBLOCAR — Suivi leads | Février
A2: Nouveau lead | B2: Appel 1 effectué | C2: En attente VIN/Photo | D2: Vérification | E2: Appel 2 effectué | F2: RDV confirmé | G2: RDV honoré | H2: Non faisable | I2: Annulé
A3: Nom | B3: Téléphone | C3: Source du lead | D3: Gouvernorat | E3: Modèle véhicule | F3: Service demandé | G3: N° Châssis (VIN) | H3: Modèle de poste | I3: Code Activation | J3: Date RDV | K3: Statut | L3: Confirm. J-1 | M3: Notes
A502: 💡 BMW/Mercedes → N° Châssis (VIN) | VW/Audi/Cupra → Modèle de poste | Code Activation = code licence acheté | Date RDV : format JJ/MM/AAAA

Sheet 📅 Mars
A1: DEBLOCAR — Suivi leads | Mars
A2: Nouveau lead | B2: Appel 1 effectué | C2: En attente VIN/Photo | D2: Vérification | E2: Appel 2 effectué | F2: RDV confirmé | G2: RDV honoré | H2: Non faisable | I2: Annulé
A3: Nom | B3: Téléphone | C3: Source du lead | D3: Gouvernorat | E3: Modèle véhicule | F3: Service demandé | G3: N° Châssis (VIN) | H3: Modèle de poste | I3: Code Activation | J3: Date RDV | K3: Statut | L3: Confirm. J-1 | M3: Notes
A502: 💡 BMW/Mercedes → N° Châssis (VIN) | VW/Audi/Cupra → Modèle de poste | Code Activation = code licence acheté | Date RDV : format JJ/MM/AAAA

Sheet 📅 Avril
A1: DEBLOCAR — Suivi leads | Avril
A2: Nouveau lead | B2: Appel 1 effectué | C2: En attente VIN/Photo | D2: Vérification | E2: Appel 2 effectué | F2: RDV confirmé | G2: RDV honoré | H2: Non faisable | I2: Annulé
A3: Nom | B3: Téléphone | C3: Source du lead | D3: Gouvernorat | E3: Modèle véhicule | F3: Service demandé | G3: N° Châssis (VIN) | H3: Modèle de poste | I3: Code Activation | J3: Date RDV | K3: Statut | L3: Confirm. J-1 | M3: Notes
A502: 💡 BMW/Mercedes → N° Châssis (VIN) | VW/Audi/Cupra → Modèle de poste | Code Activation = code licence acheté | Date RDV : format JJ/MM/AAAA

Sheet 📅 Mai
A1: DEBLOCAR — Suivi leads | Mai
A2: Nouveau lead | B2: Appel 1 effectué | C2: En attente VIN/Photo | D2: Vérification | E2: Appel 2 effectué | F2: RDV confirmé | G2: RDV honoré | H2: Non faisable | I2: Annulé
A3: Nom | B3: Téléphone | C3: Source du lead | D3: Gouvernorat | E3: Modèle véhicule | F3: Service demandé | G3: N° Châssis (VIN) | H3: Modèle de poste | I3: Code Activation | J3: Date RDV | K3: Statut | L3: Confirm. J-1 | M3: Notes
A502: 💡 BMW/Mercedes → N° Châssis (VIN) | VW/Audi/Cupra → Modèle de poste | Code Activation = code licence acheté | Date RDV : format JJ/MM/AAAA

Sheet 📅 Juin
A1: DEBLOCAR — Suivi leads | Juin
A2: Nouveau lead | B2: Appel 1 effectué | C2: En attente VIN/Photo | D2: Vérification | E2: Appel 2 effectué | F2: RDV confirmé | G2: RDV honoré | H2: Non faisable | I2: Annulé
A3: Nom | B3: Téléphone | C3: Source du lead | D3: Gouvernorat | E3: Modèle véhicule | F3: Service demandé | G3: N° Châssis (VIN) | H3: Modèle de poste | I3: Code Activation | J3: Date RDV | K3: Statut | L3: Confirm. J-1 | M3: Notes
A4: Naceur Sayari | C4: Messenger | E4: T-roc | F4: Navigation GPS | H4: 3G5035820B | K4: Nouveau lead
A5: Yacine Fendri | C5: Messenger | E5: Mercedes CLA | F5: Fonctions cachées | G5: W1K1183841N342780 | K5: Nouveau lead
A6: Salwen Mahmoud | C6: Instagram | E6: VW Golf 7.5 | F6: Apple CarPlay | H6: MST2_EU_VW_ZR_P0475T | K6: Nouveau lead
A7: Hamza Guenenna | C7: Instagram | E7: SEAT leon | F7: Fonctions cachées | H7: 5F0035824C | K7: Nouveau lead | M7: Il a contacté Yahya directement sur WhatsApp
A8: Mohamed Ben Rejeb | C8: Messenger | E8: Mercedes Classe C | F8: Activation alarme | G8: WDD2040491A363800 | K8: Nouveau lead
A9: Amir Charfi | C9: Messenger | E9: Mercedes GLC | F9: Fonctions cachées | G9: W1NK.J5GBXSF357169 | K9: Nouveau lead
A10: Hamza BD | C10: Instagram | E10: Audi Q3 | F10: Fonctions cachées | K10: En attente VIN/Photo
A11: Youssef Gomri | C11: Instagram | E11: Audi Q5 | F11: Navigation + Apple CarPlay | K11: En attente VIN/Photo | M11: lbluetooth yekhdem ken des appels téléphoniques mayekhdemsh ghne
A12: Mohamed Zaier | C12: Messenger | E12: Ibiza | F12: Fonctions cachées | K12: Nouveau lead | M12: Il a contacté l'équipe directement sur WhatsApp
A13: Ayoub Lassoued | C13: Messenger | D13: Tunis | E13: BMW X3 | F13: Navigation GPS | G13: 5UXTY5C09M9H51406 | K13: Nouveau lead | M13: Il a contacté l'équipe directement sur WhatsApp
A14: Nidhal Trabelsi | C14: Messenger | D14: Sousse | E14: Nissan | F14: Fonctions cachées | K14: Non faisable
A15: Ala eddine | C15: Instagram | K15: En attente VIN/Photo
A16: Nousair Labidi | C16: Instagram | E16: BMW Serie 7 | F16: Fonctions cachées | K16: En attente VIN/Photo
A17: Ahmed Jemai | C17: Instagram | E17: Mercedes Classe A | F17: Apple CarPlay | G17: W1K1770821V072657 | K17: Nouveau lead
A18: Nejib Sghaier | C18: Instagram | D18: Tunis | E18: VW Golf 8 | F18: Navigation + CarPlay + Alarme | K18: Nouveau lead | M18: mawjoud fel aouina
A19: Walid Chaabane | C19: Messenger | D19: Sfax | E19: Mercedes GLC | F19: Fonctions cachées | G19: W1N2533531F965819 | K19: Nouveau lead
A20: LaLou | C20: Instagram | E20: Audi Q8 | F20: Android Auto | K20: En attente VIN/Photo | M20: le bluetooth qui ne se connecte pas pour les médias
A21: wala bendhif | C21: Instagram | E21: Kia | F21: Fonctions cachées | K21: Non faisable
A22: Sofiane Ben Othman | C22: Messenger | E22: Mercedes GLA | F22: Fonctions cachées | G22: W1N2477861J328723 | K22: Nouveau lead
A23: Akram Chehdi | C23: Messenger | E23: Kia | F23: Autre | K23: Non faisable
A24: Rami Mekni | C24: Messenger | E24: Audi A3 | F24: Apple CarPlay | H24: MSTD_EU_AU_P3151 | K24: Non faisable
A25: Hamza El Faleh | C25: Messenger | D25: Gabès | E25: Mercedes GLE | F25: Fonctions cachées | G25: W1nfb5kb9pa932663 | K25: Nouveau lead
A26: Marouen Rouge | C26: Messenger | D26: France | E26: Skoda | F26: Fonctions cachées | K26: Nouveau lead
A27: Sř Ŕõùřou | C27: Messenger | E27: Mercedes GLC | F27: Fonctions cachées | G27: W1N0G8EB6MV266760 | K27: Nouveau lead | M27: Basée à Canada pour le moment
A28: Med Ali Bradai | C28: Messenger | E28: Mercedes GLC | F28: Fonctions cachées | K28: En attente VIN/Photo
A29: Mondher Farhat | C29: Messenger | E29: Mercedes Classe A | F29: Apple CarPlay | G29: W1K1770871N337878 | K29: Nouveau lead
A30: Ham Za | C30: Messenger | E30: Mercedes Classe A | F30: Fonctions cachées | K30: En attente VIN/Photo
A31: Taoufik D'hamna | C31: Messenger | E31: BMW Serie 7 | F31: Apple CarPlay | G31: WBA23EH07PCL79411 | K31: Nouveau lead
A32: Nabil Manai | C32: Messenger | E32: Mercedes GLE | F32: Navigation GPS | K32: En attente VIN/Photo
A33: Hamza Ben Youssef | C33: Messenger | E33: Mercedes GLC | F33: Autre | K33: En attente VIN/Photo
A34: Chouaib Khémiri | B34: 23844090 | C34: Messenger | E34: Mercedes GLA | F34: Apple CarPlay | G34: WDC1569441J594354 | K34: Vérification | M34: Wost jom3a habet l tunis bech ykalamna 9bal kif yet2aked wa9tech habet ==> À rappeler
A35: Mehdi Said | C35: Messenger | E35: Mercedes Classe A | F35: Navigation + Apple CarPlay | G35: WDD1760121J427735 | K35: Nouveau lead
A36: Rifaii Med | C36: Instagram | E36: BMW Serie 5 | G36: WBAXC010X0DZ94862 | K36: Nouveau lead
A37: Firas Ben Arous | B37: 56134353 | C37: Messenger | D37: Monastir | E37: Mercedes Classe C | F37: Fonctions cachées | G37: WDD2050041F002278 | K37: Nouveau lead | M37: à contacter en cas de passage à Monastir
A38: Walid Hamdi | B38: 93974881 | C38: Messenger | D38: Ben Arous | E38: Mercedes Classe C | F38: Fonctions cachées | G38: WDD2050401F060663 | K38: Vérification | M38: Veut fixer un rendez-vous pour vérifier les options activables sur sa voitures et observer les fonctions cachées
A39: Khaoula Chargui | C39: Instagram | E39: Audi Q3 | F39: Apple CarPlay | K39: En attente VIN/Photo
A40: Hammemi Med | C40: Instagram | E40: Mercedes Classe A | F40: Apple CarPlay | G40: WDD1770871J065630 | K40: Nouveau lead
...

Sheet 📅 Juillet
A1: DEBLOCAR — Suivi leads | Juillet
A2: Nouveau lead | B2: Appel 1 effectué | C2: En attente VIN/Photo | D2: Vérification | E2: Appel 2 effectué | F2: RDV confirmé | G2: RDV honoré | H2: Non faisable | I2: Annulé
A3: Nom | B3: Téléphone | C3: Source du lead | D3: Gouvernorat | E3: Modèle véhicule | F3: Service demandé | G3: N° Châssis (VIN) | H3: Modèle de poste | I3: Code Activation | J3: Date RDV | K3: Statut | L3: Confirm. J-1 | M3: Notes
A4: 💡 BMW/Mercedes → N° Châssis (VIN) | VW/Audi/Cupra → Modèle de poste | Code Activation = code licence acheté | Date RDV : format JJ/MM/AAAA
A5: Walid Hamdi | B5: 93974881 | C5: Messenger | D5: Ben Arous | E5: Mercedes Classe C | F5: Carplay + alarme | G5: WDD2050401F060663 | J5: 46223 | K5: RDV confirmé | M5: à Ben Arous
B6: 54363002 | C6: Messenger | D6: Ben Arous | E6: Mercedes GLC | F6: Alarme + navigation | K6: Vérification | M6: tawa fi 9orba, dispo jem3a jeya houwa bech yji w yheb les prix
B7: 23671050 | C7: Appel direct | D7: Kairouan | E7: Mercedes Classe A | M7: l période hethi fel Kairouan ema houwa men Sousse yheb yji houwa l tunis
A9: Hichem | B9: 29463672 | C9: WhatsApp | D9: Mahdia | E9: VW T-Roc | F9: Fonctions cachées | J9: 46215 | K9: RDV confirmé | M9: Ksour Sef
A10: Hmaida | B10: 50823880 | C10: WhatsApp | D10: Mahdia | E10: Mercedes Classe C | J10: 46215 | K10: indisponible | M10: mouch disponible
A11: Mohammed khaled hafsa | B11: 95988129 | C11: WhatsApp | D11: Mahdia | E11: Mercedes Classe C | F11: Navigation GPS | J11: 46221 | K11: Done | M11: Done
B12: 26243831 | C12: WhatsApp | D12: Mahdia | E12: VW Tiguan | F12: Fonctions cachées | J12: 46221 | K12: RDV confirmé | M12: rendez-vous fel weekend
B13: 22476484 | C13: WhatsApp | D13: Mahdia | E13: Seat Arona | F13: Fonctions cachées | J13: 46215 | K13: RDV confirmé | M13: seat arona 2021/ 14h-17h -- borj ras mahdiya confirmé
B14: 41775344201 | C14: WhatsApp | D14: Mahdia | E14: VW Golf 7 | F14: Fonctions cachées | J14: 46215 | K14: RDV confirmé
B15: 58311202 | C15: WhatsApp | D15: Mahdia | E15: Seat | F15: Apple CarPlay | J15: 46215 | K15: Done | M15: Done
A16: Iness | B16: =33660635825 -> 33660635825 | C16: WhatsApp | D16: Mahdia | E16: Seat | F16: Fonctions cachées | J16: 46215 | K16: Done | M16: done
A17: Fedy Farhat | B17: 94786000 | C17: Messenger | D17: Mahdia | E17: VW Golf 8 | F17: Fonctions cachées | J17: 46215 | K17: RDV confirmé
B18: =353894230001 -> 353894230001 | C18: WhatsApp | D18: Mahdia | E18: Skoda kushaq | F18: CarPlay + Android Auto | K18: Nouveau lead
B19: 50694256 | C19: WhatsApp | D19: Mahdia | E19: Mercedes | K19: RDV confirmé
A20: Khaled Sghaier | B20: 32474063658 | C20: WhatsApp | D20: Mahdia | E20: Mercedes G class + Porsche | F20: Navigation+ options cachées | J20: 46234 | K20: RDV confirmé | M20: Ksour Sef
A22: Rjab khlifa | B22: 20785910 | C22: WhatsApp | D22: Monastir | E22: Taigo | F22: Fonctions cachées | J22: 46214 | K22: RDV confirmé | M22: Jam
A23: Abd Razzek Chaouech | B23: 98365175 | C23: WhatsApp | D23: Monastir | E23: Mercedes GLC | F23: Activation alarme | J23: 46214 | K23: Done | M23: done
A24: Ghaith(Rafrafi Chiheb Eddine) | B24: 53633133 | C24: Messenger | D24: Monastir | E24: Mercedes Classe C | F24: Fonctions cachées | J24: 46215 | K24: Done | M24: done
A25: Farouk | B25: 55669984 | C25: WhatsApp | D25: Monastir | E25: BMW X5 | F25: Navigation GPS | G25: WBAKS410X0LE51802 | J25: 46215 | K25: Done | M25: Done
A26: Yosri | B26: 33651807162 | C26: WhatsApp | D26: Monastir | E26: Tiguan | J26: 46234 | K26: RDV confirmé | L26: Ksibet el medouni
A28: Aymen Souissi | B28: 53873929 | C28: Messenger | D28: Nabeul | F28: Fonctions cachées | H28: MST2_EU_VW_P0876D | K28: Vérification | M28: ma jewebch
A29: Wajdi Tastouri | B29: 53296780 | C29: Messenger | D29: Nabeul | E29: Seat Leon | F29: Full Link | K29: non-faisable | M29: tlaa ndou Problème de poste
A30: Rafik Soussi | B30: 92440481 | C30: Messenger | D30: Nabeul | E30: VW Tiguan | F30: Activation alarme | K30: annulé! | M30: Bech yji houwa w ken famma passage l Nabeul nkalmouh==> amalha fi Nabeul
A31: Mouldi Slama | B31: 29343172 / 52977996 | C31: Messenger | D31: Nabeul | E31: Mercedes Classe C | F31: Navigation GPS | G31: W1K2060541F025677 | J31: 46212 | K31: RDV confirmé | M31: karhba mouch andou l weekend hetha (18/19) yamel verification w yconfirmilna
B32: 98300008 | D32: Nabeul | E32: BMW X1 | F32: Nvigation + Android Auto | J32: 46239 | K32: RDV confirmé | M32: il préfère yji houwa l tunis, dispo le 05/08
A33: Marwen ben nasser | B33: 29298457 | D33: Nabeul | E33: mercedes | F33: gadget + navigateur + alarme | M33: telifounou msakker
B34: =33689390761 -> 33689390761 | C34: whatsapp | D34: Nabeul | E34: Mercedes classe A | F34: Fonctions cachées | J34: 20/07/2026 | K34: Done
A35: Mahmoud | B35: 92291903 | D35: Nabeul | E35: Mercedes GLA | F35: Fonctions cachées | G35: W1N2477841 J325383 | K35: Vérification | M35: 20/07 mouch dispo
B36: 1(418)2710736 | C36: whatsapp | D36: Hammamet | E36: Mercedes GLC | F36: Navigation | G36: W1N0J8EBXNG049669 | J36: 25/07/2026 | K36: Done | M36: Hammamet (NTG6)
A38: Soufian Ayad | B38: 28656687 | C38: Messenger | D38: Sfax | E38: Mercedes Classe C | F38: Navigation GPS | G38: WDD2050771F768301 | K38: RDV confirmé | M38: 10 aout ysefer yheb ala rendez-vous 9bal il est déja disponible
A39: Karim Lahyeni | B39: 55439027 | C39: Messenger | D39: Sfax | E39: Mercedes Classe C | F39: Fonctions cachées | K39: Vérification | M39: ma yjewebch
A40: Adly | B40: 52865865 | C40: Appel direct | D40: Sfax | E40: BMW Serie 3 | F40: Android Auto | G40: WBA51FS060FP63850 | K40: RDV confirmé | M40: jey l tunis mercredi
A41: Manai Mouhammed | B41: 95333076 | C41: WhatsApp | D41: Sfax | E41: Audi A4 | F41: Fonctions cachées | H41: MST2_EU_AU_P0314D | J41: 46214 | K41: RDV confirmé | M41: Hors ligne
B42: 52480287 | C42: WhatsApp | D42: Sfax | E42: VW Golf 8 | F42: Navigation GPS | J42: 46221 | K42: RDV confirmé | M42: confirmé par appel
B43: 27625200 | C43: Appel direct | D43: Sfax | E43: BMW | F43: Autre | J43: 46215 | K43: RDV confirmé | M43: Demain disponible fi sfax
B44: 44428814 | C44: Appel direct | D44: Sfax | E44: BMW Serie 3 | F44: Navigation GPS | J44: 46214 | K44: RDV confirmé | M44: Lyoum dispo w demain msefer
...

Sheet 📅 Août
A1: DEBLOCAR — Suivi leads | Août
A2: Nouveau lead | B2: Appel 1 effectué | C2: En attente VIN/Photo | D2: Vérification | E2: Appel 2 effectué | F2: RDV confirmé | G2: RDV honoré | H2: Non faisable | I2: Annulé
A3: Nom | B3: Téléphone | C3: Source du lead | D3: Gouvernorat | E3: Modèle véhicule | F3: Service demandé | G3: N° Châssis (VIN) | H3: Modèle de poste | I3: Code Activation | J3: Date RDV | K3: Statut | L3: Confirm. J-1 | M3: Notes
A4: Karim Ben Khedher | B4: =393270264673 -> 393270264673 | C4: WhatsApp | D4: Sousse | E4: BMW Serie 1 | F4: Fonctions cachées | J4: 46240 | K4: RDV confirmé | M4: le 06/08
A5: Asma Ben Amor | B5: 96529697 | C5: Messenger | D5: Sousse | E5: BYD | F5: Box interface android | K5: RDV confirmé | M5: ki njiw lsoussa nkalamha (ce weekend)
A6: Enis Brahem | B6: 98460459 | C6: Messenger | D6: Sousse | E6: Mercedes Classe C | F6: Apple CarPlay | G6: WDD2050401F806086 | K6: Annulé | M6: maadesh yheb yekhdem
B8: 98300008 | C8: Messenger | D8: Nabeul | E8: BMW X1 | F8: Nvigation + Android Auto | J8: 46239 | K8: RDV confirmé | M8: il préfère yji houwa l tunis, dispo le 05/08
A9: Sartoria Moderna | B9: 393475186915 | C9: Messenger | D9: Tunis | E9: VW Golf 7 | F9: Apple CarPlay | K9: Nouveau lead | M9: contact him on WhatsApp
A10: Chaari Omar | B10: 21151957 | C10: Instagram | D10: Tunis | E10: BMW Serie 1 | F10: Navigation GPS | J10: 46235 | K10: Done | M10: Done
C11: WhatsApp | E11: range rover | F11: Diagnostique | K11: Done | M11: Done
C12: WhatsApp | E12: Mercedes | F12: Diagnostique | K12: Done
B13: 58075828 | C13: WhatsApp | D13: Tunis | E13: BMW X3 | F13: Navigation GPS | J13: 46238 | K13: RDV confirmé
A14: Fares | C14: Instagram | E14: VW Golf 7 | F14: Apple CarPlay | K14: Annulé | M14: l'écran mbadel, yheb nhelouhoulou w nchoufou li ma yekhdemsh lkol b nafs soum l carplay (150d)
A15: Zied Turki | C15: Messenger | D15: Tunis | E15: BMW X1 | F15: Fonctions cachées | J15: 46242 | K15: Annulé | M15: Je w ma eejboush soum kal yzid ykhamem
A16: Mehdi Ben Brahim | B16: 23367407 | C16: WhatsApp | D16: Tunis | E16: BMW | F16: Navigation + My BMW | G16: WBA11FJ020CR12952 | J16: 46245 | K16: RDV confirmé
A17: Habib Jouini | B17: 23044865 | C17: WhatsApp | D17: Tunis | E17: BMW | F17: Diagnostique | G17: WBA7K310X07L12551 | J17: 46245 | K17: RDV confirmé
A18: Hassen Dakhlaoui | B18: 95795947 | C18: WhatsApp | D18: Tunis | E18: BMW | F18: Navigation | G18: WBA61DP0509K32865 | J18: 46245 | K18: RDV confirmé
A19: Faouzi Chaouch | B19: 29325564 | C19: WhatsApp | D19: Tunis | E19: Mercedes | F19: Navigation | G19: W1K1770841J210901 | J19: 46245 | K19: RDV confirmé
A20: Mohsen men tabarka | B20: 447378555559 | C20: WhatsApp | D20: Tunis | E20: BMW | F20: Alarme | J20: 46253 | K20: Done | M20: Done
A21: Alaeddine Boudawara | B21: 53669406 | C21: Instagram | D21: Tunis | E21: VW Passat | F21: Navigation + CarPlay + Alarme | J21: 46260 | K21: Done | M21: Done
B22: 55666603 | C22: WhatsApp | D22: Tunis | E22: BMW | F22: navigation + android auto | G22: WBA61DP0509N72520 | J22: 46260 | K22: RDV confirmé | M22: laashia
B23: 23367407 | C23: WhatsApp | D23: Tunis | E23: BMW | G23: WBA11FJ020CR12952 | J23: 46260 | K23: RDV confirmé
B24: 51039046 | C24: WhatsApp | D24: Tunis | E24: Mercedes | F24: Licences | J24: 46260 | K24: RDV confirmé
A25: Najeh ben mohamed | B25: 97914292 | C25: WhatsApp | D25: Tunis | E25: BMW X6 | F25: Options cachées | G25: 5UX33EX05R9T14905 | J25: 46261 | K25: Done | M25: Done
A27: Khaled Seghaier | B27: =32474063658 -> 32474063658 | C27: WhatsApp | D27: Mahdia | E27: Mercedes G classe | F27: start & Stop+ Navigation | G27: W1N4632761X449743 | K27: Done | M27: Done
A28: Oussama | B28: 33758077440 | C28: WhatsApp | D28: Mahdia | F28: Diagnostic | J28: 46245 | K28: RDV confirmé | M28: Ksour Sef
A29: bechir hsan | C29: WhatsApp | D29: Mahdia | E29: BMW X3 | F29: Navigation + android auto + My BMW | G29: WBA61DP0409L33251 | K29: Done | M29: Done
A30: Ramzi haj salah | B30: 33619942941 | C30: WhatsApp | D30: Mahdia | E30: Mercedes | G30: W1KAF8HB6SR262651 | J30: 46265 | K30: RDV confirmé | M30: Chebba
A32: Achref Besbes | B32: 52938355 | C32: messenger | D32: Sfax | E32: mercedes GLA | F32: Navigation | G32: W1N2477861J336601 | K32: RDV confirmé | M32: les weekends mahoush fi sfax, il préfère yji houa ki yahbet ltounes nkalmou
A33: Yacine Ichi | B33: 28121838 | C33: WhatsApp | D33: Sfax | E33: MG | K33: RDV confirmé | M33: Ken jina l sfax nkalmouh sinon tw yetaadelna l tounes
A35: Mohamed Amin Chokri | B35: 57119584 | C35: Instagram | D35: Gafsa | E35: T-Roc 2024 | F35: Navigation+alarme+Rline | K35: RDV confirmé | M35: nkalmouh ki njiw l gafsa
A37: Foued barkaoui | B37: 27557236 | C37: WhatsApp | D37: Gassrine | E37: BMW | F37: Navigation + mise a jour | K37: RDV confirmé | M37: nkalmouh k njiw ll gassrine
A510: 💡 BMW/Mercedes → N° Châssis (VIN) | VW/Audi/Cupra → Modèle de poste | Code Activation = code licence acheté | Date RDV : format JJ/MM/AAAA

Sheet 📅 Septembre
A1: DEBLOCAR — Suivi leads | Septembre
A2: Nouveau lead | B2: Appel 1 effectué | C2: En attente VIN/Photo | D2: Vérification | E2: Appel 2 effectué | F2: RDV confirmé | G2: RDV honoré | H2: Non faisable | I2: Annulé
A3: Nom | B3: Téléphone | C3: Source du lead | D3: Gouvernorat | E3: Modèle véhicule | F3: Service demandé | G3: N° Châssis (VIN) | H3: Modèle de poste | I3: Code Activation | J3: Date RDV | K3: Statut | L3: Confirm. J-1 | M3: Notes
A4: Mohamed | B4: 98269469 | C4: Messenger | D4: Tunis | E4: Skoda | F4: Navigation + CarPlay + Alarme | J4: 46268 | K4: Annulé | M4: importé de chine
A5: Tarek | B5: 98332016 | C5: Appel direct | D5: Tunis | E5: Mercedes | F5: Navigation GPS | J5: 46269 | K5: RDV honoré | M5: Done
A6: Ghassen Sanaa | B6: 33622360235 | C6: Messenger | D6: Tunis | E6: Audi Q3 | F6: Fonctions cachées | H6: MH2p_ER_AU_P2493 | J6: 46280 | K6: RDV confirmé | M6: bech yarjaali yconfirmili
A7: Med Myral | B7: 50988852 | C7: Messenger | D7: Tunis | E7: Mercedes Classe A | F7: Pack Licences + alarme + AMG | G7: WDD1183031N073481 | K7: RDV confirmé | M7: à rappeler
A8: Nadim Hammami | B8: 94800140 | C8: Messenger | D8: Tunis | E8: Mercedes Classe A | F8: Pack Licences | G8: W1K1186871N266246 | K8: RDV confirmé | M8: à rappeler
A9: Mohamed | B9: 99138321 | C9: WhatsApp | D9: Tunis | E9: Mercedes Gen20x | G9: W1KLF0JBXTA213411 | K9: RDV confirmé
A12: Elghoul Travel | B12: 44600205 | C12: WhatsApp | D12: Sfax | E12: Mercedes GLA | F12: Navigation GPS | K12: RDV confirmé
A502: 💡 BMW/Mercedes → N° Châssis (VIN) | VW/Audi/Cupra → Modèle de poste | Code Activation = code licence acheté | Date RDV : format JJ/MM/AAAA

Sheet 📅 Octobre
A1: DEBLOCAR — Suivi leads | Octobre
A2: Nouveau lead | B2: Appel 1 effectué | C2: En attente VIN/Photo | D2: Vérification | E2: Appel 2 effectué | F2: RDV confirmé | G2: RDV honoré | H2: Non faisable | I2: Annulé
A3: Nom | B3: Téléphone | C3: Source du lead | D3: Gouvernorat | E3: Modèle véhicule | F3: Service demandé | G3: N° Châssis (VIN) | H3: Modèle de poste | I3: Code Activation | J3: Date RDV | K3: Statut | L3: Confirm. J-1 | M3: Notes
A502: 💡 BMW/Mercedes → N° Châssis (VIN) | VW/Audi/Cupra → Modèle de poste | Code Activation = code licence acheté | Date RDV : format JJ/MM/AAAA

Sheet 📅 Novembre
A1: DEBLOCAR — Suivi leads | Novembre
A2: Nouveau lead | B2: Appel 1 effectué | C2: En attente VIN/Photo | D2: Vérification | E2: Appel 2 effectué | F2: RDV confirmé | G2: RDV honoré | H2: Non faisable | I2: Annulé
A3: Nom | B3: Téléphone | C3: Source du lead | D3: Gouvernorat | E3: Modèle véhicule | F3: Service demandé | G3: N° Châssis (VIN) | H3: Modèle de poste | I3: Code Activation | J3: Date RDV | K3: Statut | L3: Confirm. J-1 | M3: Notes
A502: 💡 BMW/Mercedes → N° Châssis (VIN) | VW/Audi/Cupra → Modèle de poste | Code Activation = code licence acheté | Date RDV : format JJ/MM/AAAA

Sheet 📅 Décembre
A1: DEBLOCAR — Suivi leads | Décembre
A2: Nouveau lead | B2: Appel 1 effectué | C2: En attente VIN/Photo | D2: Vérification | E2: Appel 2 effectué | F2: RDV confirmé | G2: RDV honoré | H2: Non faisable | I2: Annulé
A3: Nom | B3: Téléphone | C3: Source du lead | D3: Gouvernorat | E3: Modèle véhicule | F3: Service demandé | G3: N° Châssis (VIN) | H3: Modèle de poste | I3: Code Activation | J3: Date RDV | K3: Statut | L3: Confirm. J-1 | M3: Notes
A502: 💡 BMW/Mercedes → N° Châssis (VIN) | VW/Audi/Cupra → Modèle de poste | Code Activation = code licence acheté | Date RDV : format JJ/MM/AAAA
